#VRML_SIM R2022a utf8
WorldInfo {
}
Viewpoint {
  orientation 0.3743158485921854 0.08349172470050217 -0.9235349356679734 2.759506782127597
  position 0.5831175509433645 1.962502676719673 0.4976495633242771
}
TexturedBackground {
}
TexturedBackgroundLight {
}
RectangleArena {
  floorSize 2 4
}
Robot {
  translation -2.727597112310148e-07 1.679999939564685 -0.00020980097394540653
  rotation 0.9999999560724401 -0.00029341837377306 -4.196160110319947e-05 0.02885285690237282
  children [
    GPS {
      translation 0 0 0.08
      rotation 0 0 1 -3.1415853071795863
      children [
        Shape {
          appearance PBRAppearance {
          }
          geometry Cylinder {
            height 0.1
            radius 0.01
          }
        }
      ]
    }
    Lidar {
      translation 0 0 0.084
      rotation 0 0 1 -1.5731853071795863
      fieldOfView 1.57
      numberOfLayers 1
    }
    DEF Body Transform {
      translation 0 0 0.0415
      children [
        Shape {
          appearance PBRAppearance {
            baseColor 0 0 1
            roughness 1
            metalness 0
          }
          geometry Cylinder {
            height 0.08
            radius 0.045
          }
        }
      ]
    }
    HingeJoint {
      jointParameters HingeJointParameters {
        position -1.632830759490389e-09
        anchor 0.045 0 0.025
      }
      device [
        RotationalMotor {
          name "motor_1"
        }
      ]
      endPoint Solid {
        translation 0.04500004522150625 1.7946439938759506e-06 0.02500341462511779
        rotation 0.011836771719708521 -0.999859990025113 0.011827560282507305 4.7130488204405125
        children [
          DEF wheel Shape {
            appearance PBRAppearance {
              baseColor 1 0 0
              roughness 1
              metalness 0
            }
            geometry Cylinder {
              height 0.01
              radius 0.025
            }
          }
        ]
        boundingObject USE wheel
        physics DEF wheel_physics Physics {
        }
      }
    }
    HingeJoint {
      jointParameters HingeJointParameters {
        position -4.975371226123571e-10
        anchor -0.045 0 0.025
      }
      device [
        RotationalMotor {
          name "motor_2"
        }
      ]
      endPoint Solid {
        translation -0.044999954812926055 2.280973940990313e-06 0.025003081195356564
        rotation 0.011836771146645369 -0.9998599900376773 0.011827559793880671 4.713048820371415
        children [
          USE wheel
        ]
        name "solid(1)"
        boundingObject USE wheel
        physics USE wheel_physics
      }
    }
  ]
  boundingObject USE Body
  physics Physics {
  }
  controller "drive_my_robot"
}
Robot {
  translation 0.09999922468959282 1.6800089473709279 -0.0002098079113017834
  rotation 0.9999847095567778 0.0009994967066661135 -0.005438902369070145 0.028852865724591604
  children [
    DEF Body Transform {
      translation 0 0 0.0415
      children [
        Shape {
          appearance PBRAppearance {
            baseColor 0 0 1
            roughness 1
            metalness 0
          }
          geometry Cylinder {
            height 0.08
            radius 0.045
          }
        }
      ]
    }
    HingeJoint {
      jointParameters HingeJointParameters {
        position -1.4274146309389835e-09
        anchor 0.045 0 0.025
      }
      device [
        RotationalMotor {
          name "motor_1"
        }
      ]
      endPoint Solid {
        translation 0.04500004522150625 1.7946439953059078e-06 0.025003414625117043
        rotation 0.011836771929204551 -0.9998599900201568 0.011827560491835835 4.7130488204355565
        children [
          DEF wheel Shape {
            appearance PBRAppearance {
              baseColor 1 0 0
              roughness 1
              metalness 0
            }
            geometry Cylinder {
              height 0.01
              radius 0.025
            }
          }
        ]
        boundingObject USE wheel
        physics DEF wheel_physics Physics {
        }
      }
    }
    HingeJoint {
      jointParameters HingeJointParameters {
        position -1.4524141884236403e-09
        anchor -0.045 0 0.025
      }
      device [
        RotationalMotor {
          name "motor_2"
        }
      ]
      endPoint Solid {
        translation -0.044999954812926055 2.280973942005222e-06 0.025003081195355815
        rotation 0.011836771311425022 -0.9998599900337789 0.01182755995852857 4.713048820367517
        children [
          USE wheel
        ]
        name "solid(1)"
        boundingObject USE wheel
        physics USE wheel_physics
      }
    }
  ]
  name "robot(1)"
  boundingObject USE Body
  physics Physics {
  }
  controller "my_controller"
}
Solid {
  translation 0.09000222922974696 -0.37999777077025293 0.200950000000299
  rotation -0.7131048237963923 0.7010482659531535 -0.003583166531535173 3.069371855653116e-15
  scale 5 5 5
  children [
    DEF box_obstacle Shape {
      appearance PBRAppearance {
        baseColor 1 1 0
        roughness 1
        metalness 0
      }
      geometry Box {
        size 0.1 0.1 0.1
      }
    }
  ]
  boundingObject USE box_obstacle
  physics Physics {
  }
}
Solid {
  translation -0.14 -1.37 0.21540383647294872
  rotation 0.9597723513556138 0.2159487790550131 -0.1794523847653337 4.330150175755426e-17
  scale 7 7 7
  children [
    DEF box_obstacle Shape {
      appearance PBRAppearance {
        baseColor 1 1 0
        roughness 1
        metalness 0
      }
      geometry Box {
        size 0.1 0.1 0.1
      }
    }
  ]
  name "solid(4)"
  boundingObject USE box_obstacle
  physics Physics {
  }
}
Solid {
  translation 0.7300022292297467 -0.7699977707702533 0.200950000000299
  rotation -0.7096019357985381 0.7046027098764495 0.00033755848613286607 3.031068513143213e-15
  scale 5 5 5
  children [
    DEF box_obstacle Shape {
      appearance PBRAppearance {
        baseColor 1 1 0
        roughness 1
        metalness 0
      }
      geometry Box {
        size 0.1 0.1 0.1
      }
    }
  ]
  name "solid(3)"
  boundingObject USE box_obstacle
  physics Physics {
  }
}
Solid {
  translation 0.7500018037465097 0.5899995210864253 0.2009494841477582
  rotation 0.44857888508179483 -0.5046699147052625 -0.7376213534396608 2.605764462228564e-06
  scale 5 5 5
  children [
    DEF box_obstacle Shape {
      appearance PBRAppearance {
        baseColor 1 1 0
        roughness 1
        metalness 0
      }
      geometry Box {
        size 0.1 0.1 0.1
      }
    }
  ]
  name "solid(1)"
  boundingObject USE box_obstacle
  physics Physics {
  }
}
Solid {
  translation -0.29 0.59 0.19909120578502518
  rotation 0.0738438328171964 -0.9968917430321125 -0.027457986620700762 5.773341187631256e-17
  scale 8 8 8
  children [
    DEF box_obstacle Shape {
      appearance PBRAppearance {
        baseColor 1 1 0
        roughness 1
        metalness 0
      }
      geometry Box {
        size 0.1 0.1 0.1
      }
    }
  ]
  name "solid(2)"
  boundingObject USE box_obstacle
  physics Physics {
  }
}
Solid {
  translation 0.7 -1.7 0
  scale 3 3 3
  children [
    Shape {
      appearance PBRAppearance {
        baseColor 1 0 0
        roughness 1
        metalness 0
      }
      geometry Cone {
        bottomRadius 0.05
        height 0.1
      }
    }
  ]
  name "solid(5)"
}
