#VRML_SIM R2022a utf8
WorldInfo {
}
Viewpoint {
  orientation 0.12671363402588587 0.09992550490365716 -0.986893382499702 1.8887912849089157
  position 0.6686429243169301 3.207853614068312 0.7530624746626879
}
TexturedBackground {
}
TexturedBackgroundLight {
}
RectangleArena {
  floorSize 2 4
}
Robot {
  translation 0 1.68 0
  rotation 0 1 0 0
  children [
    GPS {
      translation 0 0 0.08
      rotation 0 0 1 -3.1415853071795863
      children [
        Shape {
          appearance PBRAppearance {
          }
          geometry Cylinder {
            height 0.1
            radius 0.01
          }
        }
      ]
    }
    Lidar {
      translation 0 0 0.084
      rotation 0 0 1 -1.5731853071795863
      fieldOfView 1.57
      numberOfLayers 1
    }
    DEF Body Transform {
      translation 0 0 0.0415
      children [
        Shape {
          appearance PBRAppearance {
            baseColor 0 0 1
            roughness 1
            metalness 0
          }
          geometry Cylinder {
            height 0.08
            radius 0.045
          }
        }
      ]
    }
    HingeJoint {
      jointParameters HingeJointParameters {
        anchor 0.045 0 0.025
      }
      device [
        RotationalMotor {
          name "motor_1"
        }
      ]
      endPoint Solid {
        translation 0.04500004522150625 1.7946439883004456e-06 0.02500341462512072
        rotation 0.011836770902868722 -0.9998599900444379 0.011827559466320605 4.71304882045984
        children [
          DEF wheel Shape {
            appearance PBRAppearance {
              baseColor 1 0 0
              roughness 1
              metalness 0
            }
            geometry Cylinder {
              height 0.01
              radius 0.025
            }
          }
        ]
        boundingObject USE wheel
        physics DEF wheel_physics Physics {
        }
      }
    }
    HingeJoint {
      jointParameters HingeJointParameters {
        anchor -0.045 0 0.025
      }
      device [
        RotationalMotor {
          name "motor_2"
        }
      ]
      endPoint Solid {
        translation -0.044999954812926055 2.280973939457304e-06 0.0250030811953577
        rotation 0.011836770897747482 -0.9998599900435657 0.01182755954518179 4.713048820377304
        children [
          USE wheel
        ]
        name "solid(1)"
        boundingObject USE wheel
        physics USE wheel_physics
      }
    }
  ]
  boundingObject USE Body
  physics Physics {
  }
  controller "drive_my_robot"
}
Solid {
  translation 0.09 -0.38 0.25
  scale 5 5 5
  children [
    DEF box_obstacle Shape {
      appearance PBRAppearance {
        baseColor 1 1 0
        roughness 1
        metalness 0
      }
      geometry Box {
        size 0.1 0.1 0.1
      }
    }
  ]
  boundingObject USE box_obstacle
  physics Physics {
  }
}
Solid {
  translation -0.14 -1.37 0.35
  scale 7 7 7
  children [
    DEF box_obstacle Shape {
      appearance PBRAppearance {
        baseColor 1 1 0
        roughness 1
        metalness 0
      }
      geometry Box {
        size 0.1 0.1 0.1
      }
    }
  ]
  name "solid(4)"
  boundingObject USE box_obstacle
  physics Physics {
  }
}
Solid {
  translation 0.73 -0.77 0.25
  scale 5 5 5
  children [
    DEF box_obstacle Shape {
      appearance PBRAppearance {
        baseColor 1 1 0
        roughness 1
        metalness 0
      }
      geometry Box {
        size 0.1 0.1 0.1
      }
    }
  ]
  name "solid(3)"
  boundingObject USE box_obstacle
  physics Physics {
  }
}
Solid {
  translation 0.75 0.59 0.25
  scale 5 5 5
  children [
    DEF box_obstacle Shape {
      appearance PBRAppearance {
        baseColor 1 1 0
        roughness 1
        metalness 0
      }
      geometry Box {
        size 0.1 0.1 0.1
      }
    }
  ]
  name "solid(1)"
  boundingObject USE box_obstacle
  physics Physics {
  }
}
Solid {
  translation -0.29 0.59 0.41
  scale 8 8 8
  children [
    DEF box_obstacle Shape {
      appearance PBRAppearance {
        baseColor 1 1 0
        roughness 1
        metalness 0
      }
      geometry Box {
        size 0.1 0.1 0.1
      }
    }
  ]
  name "solid(2)"
  boundingObject USE box_obstacle
  physics Physics {
  }
}
Solid {
  translation 0.7 -1.7 0
  scale 3 3 3
  children [
    Shape {
      appearance PBRAppearance {
        baseColor 1 0 0
        roughness 1
        metalness 0
      }
      geometry Cone {
        bottomRadius 0.05
        height 0.1
      }
    }
  ]
  name "solid(5)"
}
